Workbook
Name IMP_DONNEES: OFFSET(IMPORT!$A$1,0,0,1000,1000)
Name IMP_ENTETES: OFFSET(IMPORT!$A$1,0,0,1,1000)

Sheet GUIDE
A1: GUIDE D'UTILISATION — OUTIL HSE
A5: 1. À QUOI SERT CET OUTIL
A6: • L'outil calcule quatre indices de performance HSE pour un chantier : santé, sécurité, environnement et social
A7: • Il ne produit aucun indice global : les quatre dimensions ne se compensent pas
A8: • Un indice se lit toujours avec sa décomposition par paramètre et ses alertes, jamais seul
A9: • Les données proviennent de la grille d'évaluation renseignée sur le chantier, puis saisie dans KoboToolbox
A11: 2. MODE D'EMPLOI, ÉTAPE PAR ÉTAPE
A12: Étape | B12: Action | C12: Comment
A13: 1 | B13: Exporter les données de KoboToolbox | C13: Données → Téléchargements. Type XLS, « Valeurs et en-têtes XML », sans cocher « Inclure les groupes dans les en-têtes »
A14: 2 | B14: Coller l'export dans la feuille IMPORT | C14: Vider d'abord la feuille, puis coller à partir de la cellule A1 par Collage spécial → Valeurs
A15: 3 | B15: Choisir la visite dans la feuille SAISIE | C15: Saisir le code du chantier en B4 et la date en B5. Ce sont les deux seules cellules orange de l'en-tête
A16: 4 | B16: Vérifier la colonne Contrôle | C16: Toute ligne en rouge signale une anomalie : valeur manquante, hors champ, NA interdit ou dénominateur invalide. Corriger dans les colonnes orange G et H
A17: 5 | B17: Lire la feuille RAPPORT | C17: Alertes, quatre indices, décomposition par paramètre, sous-indicateurs les plus faibles
A18: 6 | B18: Archiver la visite dans la feuille SUIVI | C18: Copier la ligne 5, puis la coller en valeurs à la suite de l'historique
A20: 3. CODE COULEUR DES CELLULES
A21: Orange | B21: cellule à remplir par l'utilisateur
A22: Gris | B22: cellule automatique, à ne pas modifier
A23: Rouge | B23: anomalie à corriger
A26: 4. ÉCHELLE DE LECTURE DES INDICES
A27: Indice | B27: Niveau | C27: Signification | D27: Orientation
A28: 0 à moins de 20 | B28: Initial | C28: Les exigences ne sont pas satisfaites. Ce qui existe relève du hasard, non d'une organisation. | D28: Mettre en place immédiatement le socle réglementaire
A29: 20 à moins de 40 | B29: Basique | C29: Quelques dispositions isolées, sans lien entre elles. | D29: Combler les manques les plus exposants
A30: 40 à moins de 60 | B30: Défini | C30: La plupart des exigences font l'objet d'une disposition, mais l'application est inégale. | D30: Généraliser à l'ensemble du chantier
A31: 60 à moins de 80 | B31: Maîtrisé | C31: Les exigences sont satisfaites et appliquées de façon régulière. | D31: Établir la traçabilité
A32: 80 à 100 | B32: Optimisé | C32: Les exigences sont satisfaites, appliquées et tracées. | D32: Maintenir et contrôler périodiquement
A33: Les couleurs concernent uniquemernt la note obtenu par la dimension après le calcul
A36: 5. RÈGLES GÉNÉRALES DE COTATION
A37: Binaire | B37: 1 = l'exigence est entièrement satisfaite ; 0 = elle ne l'est pas. Tout ou rien : un seul élément non conforme de la famille fait tomber à 0
A38: Libellés « Absence de… » | B38: Coter 1 si aucune situation non conforme n'est constatée ; 0 dès qu'une seule l'est
A39: Maturité | B39: Choisir l'échelon dont la description correspond à ce qui est observé. Coter à la fin du parcours complet
A40: Taux | B40: Relever le numérateur et le dénominateur, jamais un pourcentage estimé. Le calcul est fait par l'outil
A41: Preuve écrite | B41: Pour une formation, une séance, une désignation ou un document, la déclaration orale ne suffit pas : la trace doit porter une date, un objet et un nom. À défaut, coter 0. Un document conservé au seul siège compte 0
A42: Non applicable (NA) | B42: Uniquement si le critère écrit dans la colonne « NA si » est rempli. Lorsque la colonne indique « NA interdit », il faut coter obligatoirement
A43: Emprise observée | B43: Le front de travaux et la base-vie et les installations qui le desservent
A44: Projets linéaires | B44: Pour un projet couvrant plusieurs voies, l'unité observée est le tronçon en cours de travaux, ainsi que la base - vie et le cas échéant, la qui centrale qui la desservent
A45: Entreprises | B45: Les documents sont demandés aux entreprises présentes sur le tronçon observé. Les tâcherons relèvent de SO-CNF-1.3 et 1.4
A46: Cabinet d'aisances | B46: WC ou latrine en état de fonctionner. Ni douche, ni lavabo, ni urinoir
A48: 6. RÈGLES DE COTATION DES 131 SOUS-INDICATEURS
A49: Code | B49: Sous-indicateur | C49: Type | D49: Règle de cotation | E49: NA si
A50: SA-PRV-1.1 | B50: Présence d'un moyen d'arrosage en état de fonctionner et affecté au chantier | C50: Binaire | D50: Camion-citerne, tonne à eau, cuve avec pompe ou tuyau raccordé. Doit être présent, en état de marche et affecté au chantier, non emprunté. | E50: NA interdit
...

Sheet REFERENTIEL
A1: REFERENTIEL HSE
A3: DIMENSION | B3: PARAMETRE | C3: CODE INDICATEUR | D3: INDICATEUR | E3: CODE SOUS INDICATEUR | F3: SOUS INDICATEUR | G3: CODE KOBO | H3: TYPE | I3: NA AUTORISE | J3: FACTEUR
A4: Santé | B4: Prévention | C4: SA-PRV-1 | D4: Maîtrise des poussières à la source | E4: SA-PRV-1.1 | F4: Présence d'un moyen d'arrosage en état de fonctionner et affecté au chantier | G4: SA_PRV_1_1 | H4: Binaire | I4: NON | J4: 1
A5: Santé | B5: Prévention | C5: SA-PRV-1 | D5: Maîtrise des poussières à la source | E5: SA-PRV-1.2 | F5: Présence de bâches ou de couverture sur les stocks de matériaux fins | G5: SA_PRV_1_2 | H5: Binaire | I5: OUI | J5: 1
A6: Santé | B6: Prévention | C6: SA-PRV-1 | D6: Maîtrise des poussières à la source | E6: SA-PRV-1.3 | F6: Absence de nuage de poussière constaté au cours de la visite | G6: SA_PRV_1_3 | H6: Binaire | I6: NON | J6: 1
A7: Santé | B7: Prévention | C7: SA-PRV-1 | D7: Maîtrise des poussières à la source | E7: SA-PRV-1.4 | F7: Présence d’eau au poste de découpe humide | G7: SA_PRV_1_4 | H7: Binaire | I7: OUI | J7: 1
A8: Santé | B8: Prévention | C8: SA-PRV-2 | D8: Salubrité des lieux de travail et maîtrise des vecteurs | E8: SA-PRV-2.1 | F8: Présence d'un planning de nettoyage du chantier | G8: SA_PRV_2_1 | H8: Binaire | I8: NON | J8: 1
A9: Santé | B9: Prévention | C9: SA-PRV-2 | D9: Salubrité des lieux de travail et maîtrise des vecteurs | E9: SA-PRV-2.2 | F9: Absence de déchets alimentaires ou de restes de repas abandonnés sur l'emprise | G9: SA_PRV_2_2 | H9: Binaire | I9: NON | J9: 1
A10: Santé | B10: Prévention | C10: SA-PRV-2 | D10: Salubrité des lieux de travail et maîtrise des vecteurs | E10: SA-PRV-2.3 | F10: Présence d'un drainage ou d'un écoulement entretenu évitant la stagnation d'eau | G10: SA_PRV_2_3 | H10: Binaire | I10: NON | J10: 1
A11: Santé | B11: Prévention | C11: SA-PRV-2 | D11: Salubrité des lieux de travail et maîtrise des vecteurs | E11: SA-PRV-2.4 | F11: Absence de récipients, pneus ou débris retenant l'eau sur l'emprise | G11: SA_PRV_2_4 | H11: Binaire | I11: NON | J11: 1
A12: Santé | B12: Prévention | C12: SA-PRV-3 | D12: Information et sensibilisation des travailleurs aux risques sanitaires | E12: SA-PRV-3.1 | F12: Tenue d'un registre des séances de sensibilisation aux risques sanitaires | G12: SA_PRV_3_1 | H12: Binaire | I12: NON | J12: 1
A13: Santé | B13: Prévention | C13: SA-PRV-3 | D13: Information et sensibilisation des travailleurs aux risques sanitaires | E13: SA-PRV-3.2 | F13: Présence d'un responsable HSE désigné sur le chantier | G13: SA_PRV_3_2 | H13: Binaire | I13: NON | J13: 1
A14: Santé | B14: Prévention | C14: SA-PRV-3 | D14: Information et sensibilisation des travailleurs aux risques sanitaires | E14: SA-PRV-3.3 | F14: Taux de travailleurs ayant reçu une induction sur les risques sanitaires | G14: SA_PRV_3_3 | H14: Taux | I14: NON | J14: 1
A15: Santé | B15: Prévention | C15: SA-PRV-3 | D15: Information et sensibilisation des travailleurs aux risques sanitaires | E15: SA-PRV-3.4 | F15: Présence d'affiches sur les règles d'hygiène du chantier | G15: SA_PRV_3_4 | H15: Binaire | I15: NON | J15: 1
... A134: Social | B134: Conformité | C134: SO-CNF-3 | D134: Conformité aux engagements sociaux du plan de gestion | E134: SO-CNF-3.4 | F134: Présence d’une trace de suite donnée aux écarts sociaux relevés lors des missions de contrôle | G134: SO_CNF_3_4 | H134: Binaire | I134: OUI | J134: 1

Sheet IMPORT
A1: code_chantier | B1: date_visite | C1: heure_debut | D1: heure_fin | E1: type_ouvrage | F1: phase | G1: effectif_total | H1: effectif_h | I1: effectif_f | J1: entreprise | K1: meteo_24h | L1: observateur | M1: n_SA_PRV_1 | N1: SA_PRV_1_1 | O1: SA_PRV_1_1_obs | P1: SA_PRV_1_2 | Q1: SA_PRV_1_2_obs | R1: SA_PRV_1_3 | S1: SA_PRV_1_3_obs | T1: SA_PRV_1_4 | U1: SA_PRV_1_4_obs | V1: n_SA_PRV_2 | W1: SA_PRV_2_1 | X1: SA_PRV_2_1_obs | Y1: SA_PRV_2_2 | Z1: SA_PRV_2_2_obs | AA1: SA_PRV_2_3 | AB1: SA_PRV_2_3_obs | AC1: SA_PRV_2_4 | AD1: SA_PRV_2_4_obs | AE1: n_SA_PRV_3 | AF1: SA_PRV_3_1 | AG1: SA_PRV_3_1_obs | AH1: SA_PRV_3_2 | AI1: SA_PRV_3_2_obs | AJ1: SA_PRV_3_3_num | AK1: SA_PRV_3_3_den | AL1: SA_PRV_3_3_obs | AM1: SA_PRV_3_4 | AN1: SA_PRV_3_4_obs | AO1: n_SA_PRT_1 | AP1: SA_PRT_1_1 | AQ1: SA_PRT_1_1_obs | AR1: SA_PRT_1_2 | AS1: SA_PRT_1_2_obs | AT1: SA_PRT_1_3 | AU1: SA_PRT_1_3_obs | AV1: SA_PRT_1_4 | AW1: SA_PRT_1_4_obs | AX1: n_SA_PRT_2 | AY1: SA_PRT_2_1 | AZ1: SA_PRT_2_1_obs | BA1: SA_PRT_2_2 | BB1: SA_PRT_2_2_obs | BC1: SA_PRT_2_3 | BD1: SA_PRT_2_3_obs | BE1: SA_PRT_2_4 | BF1: SA_PRT_2_4_obs | BG1: n_SA_CNF_1 | BH1: SA_CNF_1_1 | BI1: SA_CNF_1_1_obs | BJ1: SA_CNF_1_2_num | BK1: SA_CNF_1_2_den | BL1: SA_CNF_1_2_obs | BM1: SA_CNF_1_3 | BN1: SA_CNF_1_3_obs | BO1: SA_CNF_1_4_num | BP1: SA_CNF_1_4_den | BQ1: SA_CNF_1_4_obs | BR1: n_SA_CNF_2 | BS1: SA_CNF_2_1_num | BT1: SA_CNF_2_1_den | BU1: SA_CNF_2_1_obs | BV1: SA_CNF_2_2_statut | BW1: SA_CNF_2_2_num | BX1: SA_CNF_2_2_den | BY1: SA_CNF_2_2_obs | BZ1: SA_CNF_2_3 | CA1: SA_CNF_2_3_obs | CB1: SA_CNF_2_4 | CC1: SA_CNF_2_4_obs | CD1: n_SA_CNF_3 | CE1: SA_CNF_3_1 | CF1: SA_CNF_3_1_obs | CG1: SA_CNF_3_2 | CH1: SA_CNF_3_2_obs | CI1: SA_CNF_3_3 | CJ1: SA_CNF_3_3_obs | CK1: SA_CNF_3_4 | CL1: SA_CNF_3_4_obs | CM1: n_SE_PRV_1 | CN1: SE_PRV_1_1 | CO1: SE_PRV_1_1_obs | CP1: SE_PRV_1_2 | CQ1: SE_PRV_1_2_obs | CR1: SE_PRV_1_3 | CS1: SE_PRV_1_3_obs | CT1: SE_PRV_1_4 | CU1: SE_PRV_1_4_obs | CV1: n_SE_PRV_2 | CW1: SE_PRV_2_1 | CX1: SE_PRV_2_1_obs | CY1: SE_PRV_2_2 | CZ1: SE_PRV_2_2_obs | DA1: SE_PRV_2_3 | DB1: SE_PRV_2_3_obs | DC1: SE_PRV_2_4 | DD1: SE_PRV_2_4_obs | DE1: n_SE_PRV_3 | DF1: SE_PRV_3_1 | DG1: SE_PRV_3_1_obs | DH1: SE_PRV_3_2_statut | DI1: SE_PRV_3_2_num | DJ1: SE_PRV_3_2_den | DK1: SE_PRV_3_2_obs | DL1: SE_PRV_3_3 | DM1: SE_PRV_3_3_obs | DN1: SE_PRV_3_4 | DO1: SE_PRV_3_4_obs | DP1: n_SE_PRT_1 | DQ1: SE_PRT_1_1 | DR1: SE_PRT_1_1_obs | DS1: SE_PRT_1_2 | DT1: SE_PRT_1_2_obs | DU1: SE_PRT_1_3 | DV1: SE_PRT_1_3_obs | DW1: SE_PRT_1_4 | DX1: SE_PRT_1_4_obs | DY1: n_SE_PRT_2 | DZ1: SE_PRT_2_1 | EA1: SE_PRT_2_1_obs | EB1: SE_PRT_2_2 | EC1: SE_PRT_2_2_obs | ED1: SE_PRT_2_3 | EE1: SE_PRT_2_3_obs | EF1: SE_PRT_2_4 | EG1: SE_PRT_2_4_obs | EH1: n_SE_PRT_3 | EI1: SE_PRT_3_1 | EJ1: SE_PRT_3_1_obs | EK1: SE_PRT_3_2 | EL1: SE_PRT_3_2_obs | EM1: SE_PRT_3_3 | EN1: SE_PRT_3_3_obs | EO1: SE_PRT_3_4 | EP1: SE_PRT_3_4_obs | EQ1: n_SE_CNF_1 | ER1: SE_CNF_1_1 | ES1: SE_CNF_1_1_obs | ET1: SE_CNF_1_2 | EU1: SE_CNF_1_2_obs | EV1: SE_CNF_1_3 | EW1: SE_CNF_1_3_obs | EX1: SE_CNF_1_4 | EY1: SE_CNF_1_4_obs | EZ1: n_SE_CNF_2 | FA1: SE_CNF_2_1 | FB1: SE_CNF_2_1_obs | FC1: SE_CNF_2_2 | FD1: SE_CNF_2_2_obs | FE1: SE_CNF_2_3 | FF1: SE_CNF_2_3_obs | FG1: SE_CNF_2_4 | FH1: SE_CNF_2_4_obs | FI1: n_SE_CNF_3 | FJ1: SE_CNF_3_1 | FK1: SE_CNF_3_1_obs | FL1: SE_CNF_3_2 | FM1: SE_CNF_3_2_obs | FN1: SE_CNF_3_3_statut | FO1: SE_CNF_3_3_num | FP1: SE_CNF_3_3_den | FQ1: SE_CNF_3_3_obs | FR1: SE_CNF_3_4 | FS1: SE_CNF_3_4_obs | FT1: n_EN_PRV_1 | FU1: EN_PRV_1_1 | FV1: EN_PRV_1_1_obs | FW1: EN_PRV_1_2 | FX1: EN_PRV_1_2_obs | FY1: EN_PRV_1_3 | FZ1: EN_PRV_1_3_obs | GA1: EN_PRV_1_4_num | GB1: EN_PRV_1_4_den | GC1: EN_PRV_1_4_obs | GD1: n_EN_PRV_2 | GE1: EN_PRV_2_1 | GF1: EN_PRV_2_1_obs | GG1: EN_PRV_2_2 | GH1: EN_PRV_2_2_obs | GI1: EN_PRV_2_3 | GJ1: EN_PRV_2_3_obs | GK1: EN_PRV_2_4 | GL1: EN_PRV_2_4_obs | GM1: n_EN_PRV_3 | GN1: EN_PRV_3_1 | GO1: EN_PRV_3_1_obs | GP1: EN_PRV_3_2 | GQ1: EN_PRV_3_2_obs | GR1: EN_PRV_3_3 | GS1: EN_PRV_3_3_obs | GT1: EN_PRV_3_4 | GU1: EN_PRV_3_4_obs | GV1: n_EN_PRT_1 | GW1: EN_PRT_1_1 | GX1: EN_PRT_1_1_obs | GY1: EN_PRT_1_2 | GZ1: EN_PRT_1_2_obs | HA1: EN_PRT_1_3 | HB1: EN_PRT_1_3_obs | HC1: EN_PRT_1_4 | HD1: EN_PRT_1_4_obs | HE1: n_EN_PRT_2 | HF1: EN_PRT_2_1 | HG1: EN_PRT_2_1_obs | HH1: EN_PRT_2_2 | HI1: EN_PRT_2_2_obs | HJ1: EN_PRT_2_3 | HK1: EN_PRT_2_3_obs | HL1: EN_PRT_2_4 | HM1: EN_PRT_2_4_obs | HN1: n_EN_CNF_1 | HO1: EN_CNF_1_1 | HP1: EN_CNF_1_1_obs | HQ1: EN_CNF_1_2 | HR1: EN_CNF_1_2_obs | HS1: EN_CNF_1_3 | HT1: EN_CNF_1_3_obs | HU1: EN_CNF_1_4 | HV1: EN_CNF_1_4_obs | HW1: n_EN_CNF_2 | HX1: EN_CNF_2_1 | HY1: EN_CNF_2_1_obs | HZ1: EN_CNF_2_2 | IA1: EN_CNF_2_2_obs | IB1: EN_CNF_2_3 | IC1: EN_CNF_2_3_obs | ID1: EN_CNF_2_4 | IE1: EN_CNF_2_4_obs | IF1: n_EN_CNF_3 | IG1: EN_CNF_3_1 | IH1: EN_CNF_3_1_obs | II1: EN_CNF_3_2 | IJ1: EN_CNF_3_2_obs | IK1: EN_CNF_3_3 | IL1: EN_CNF_3_3_obs | IM1: EN_CNF_3_4 | IN1: EN_CNF_3_4_obs | IO1: n_SO_PRV_1 | IP1: SO_PRV_1_1 | IQ1: SO_PRV_1_1_obs | IR1: SO_PRV_1_2 | IS1: SO_PRV_1_2_obs | IT1: SO_PRV_1_3 | IU1: SO_PRV_1_3_obs | IV1: SO_PRV_1_4 | IW1: SO_PRV_1_4_obs | IX1: n_SO_PRV_2 | IY1: SO_PRV_2_1 | IZ1: SO_PRV_2_1_obs | JA1: SO_PRV_2_2 | JB1: SO_PRV_2_2_obs | JC1: SO_PRV_2_3 | JD1: SO_PRV_2_3_obs | JE1: SO_PRV_2_4 | JF1: SO_PRV_2_4_obs | JG1: n_SO_PRT_1 | JH1: SO_PRT_1_1 | JI1: SO_PRT_1_1_obs | JJ1: SO_PRT_1_2 | JK1: SO_PRT_1_2_obs | JL1: SO_PRT_1_3 | JM1: SO_PRT_1_3_obs | JN1: SO_PRT_1_4 | JO1: SO_PRT_1_4_obs | JP1: n_SO_PRT_2 | JQ1: SO_PRT_2_1 | JR1: SO_PRT_2_1_obs | JS1: SO_PRT_2_2 | JT1: SO_PRT_2_2_obs | JU1: SO_PRT_2_3 | JV1: SO_PRT_2_3_obs | JW1: SO_PRT_2_4 | JX1: SO_PRT_2_4_obs | JY1: n_SO_PRT_3 | JZ1: SO_PRT_3_1 | KA1: SO_PRT_3_1_obs | KB1: SO_PRT_3_2 | KC1: SO_PRT_3_2_obs | KD1: SO_PRT_3_3 | KE1: SO_PRT_3_3_obs | KF1: SO_PRT_3_4 | KG1: SO_PRT_3_4_obs | KH1: n_SO_CNF_1 | KI1: SO_CNF_1_1 | KJ1: SO_CNF_1_1_obs | KK1: SO_CNF_1_2 | KL1: SO_CNF_1_2_obs | KM1: SO_CNF_1_3 | KN1: SO_CNF_1_3_obs | KO1: SO_CNF_1_4 | KP1: SO_CNF_1_4_obs | KQ1: n_SO_CNF_2 | KR1: SO_CNF_2_1 | KS1: SO_CNF_2_1_obs | KT1: SO_CNF_2_2 | KU1: SO_CNF_2_2_obs | KV1: SO_CNF_2_3_num | KW1: SO_CNF_2_3_den | KX1: SO_CNF_2_3_obs | KY1: n_SO_CNF_3 | KZ1: SO_CNF_3_1 | LA1: SO_CNF_3_1_obs | LB1: SO_CNF_3_2 | LC1: SO_CNF_3_2_obs | LD1: SO_CNF_3_3 | LE1: SO_CNF_3_3_obs | LF1: SO_CNF_3_4 | LG1: SO_CNF_3_4_obs | LH1: photo_1 | LI1: photo_1_URL | LJ1: photo_1_leg | LK1: photo_2 | LL1: photo_2_URL | LM1: photo_2_leg | LN1: photo_3 | LO1: photo_3_URL | LP1: photo_3_leg | LQ1: photo_4 | LR1: photo_4_URL | LS1: photo_4_leg | LT1: photo_5 | LU1: photo_5_URL | LV1: photo_5_leg | LW1: _id | LX1: _uuid | LY1: _submission_time | LZ1: _validation_status | MA1: _status | MB1: _submitted_by | MC1: __version__ | MD1: meta/rootUuid | ME1: _index
A2: MAAC | B2: 46283 | C2: 11:30:00.000+01:00 | D2: 12:20:00.000+01:00 | E2: batiment | F2: terrassement | G2: 171 | H2: 171 | I2: 0 | J2: ACC | K2: pluie_jour | L2: SODJI Ruddy | N2: 1 | P2: 0 | R2: 1 | T2: NA | W2: 1 | Y2: 1 | AA2: 1 | AC2: 1 | AF2: 1 | AH2: 1 | AJ2: 0 | AK2: 171 | AL2: Aucun registre vu lors de la visite pouvant affirmer la traçabilité des induction effectuées | AM2: 0 | AP2: NA | AR2: NA | AT2: NA | AV2: 1 | AY2: 1 | BA2: 1 | BC2: 1 | BE2: 0 | BH2: 1 | BJ2: 55 | BK2: 171 | BM2: 1 | BO2: 171 | BP2: 171 | BS2: 10 | BT2: 171 | BV2: N | BZ2: 5 | CB2: 1 | CE2: 1 | CG2: 1 | CI2: 1 | CK2: 1 | CN2: 1 | CP2: 1 | CR2: 1 | CT2: 1 | CW2: NA | CY2: 1 | DA2: NA | DC2: NA | DD2: Début d’installation | DF2: 1 | DH2: A | DI2: 4 | DJ2: 4 | DL2: 1 | DN2: 1 | DQ2: 4 | DS2: NA | DU2: 1 | DW2: 1 | DZ2: 1 | EB2: 1 | ED2: 0 | EF2: 1 | EI2: 1 | EK2: 1 | EM2: 1 | EO2: 1 | ER2: 1 | ET2: 1 | EV2: 0 | EX2: 0 | FA2: 1 | FC2: NA | FE2: 1 | FG2: 1 | FJ2: 0 | FL2: 0 | FN2: A | FO2: 0 | FP2: 4 | FR2: 0 | FU2: 1 | FW2: 1 | FY2: 1 | GA2: 0 | GB2: 171 | GC2: Aucun registre ou document observer lors de la visite et qui retrace l’induction ou la sensibilisation sur le tri des déchets | GE2: 1 | GG2: 1 | GI2: 1 | GK2: 1 | GN2: 1 | GP2: 1 | GR2: 1 | GT2: NA | GW2: 1 | GY2: 1 | HA2: 1 | HC2: 1 | HF2: 1 | HH2: 1 | HJ2: 1 | HL2: NA | HO2: 1 | HQ2: 3 | HS2: 1 | HU2: 0 | HX2: 1 | HZ2: 1 | IB2: 1 | ID2: 1 | IG2: 1 | II2: 1 | IK2: 1 | IM2: 1 | IP2: 1 | IR2: 0 | IT2: 1 | IV2: 1 | IY2: 1 | JA2: 1 | JC2: 1 | JE2: 1 | JH2: 1 | JJ2: 1 | JL2: NA | JN2: 1 | JQ2: 1 | JS2: 1 | JU2: 0 | JW2: 1 | JZ2: 1 | KB2: 1 | KD2: 1 | KF2: NA | KI2: 1 | KK2: 1 | KM2: NA | KO2: NA | KR2: 1 | KT2: NA | KV2: 0 | KW2: 171 | KX2: Aucun registre ou document du personnel observer lors de la visite et qui mentionne la date de naissance des travailleurs | KZ2: 1 | LB2: 1 | LD2: 1 | LF2: 0 | LH2: IMG_5528-21_18_58.jpeg | LI2: https://kf.kobotoolbox.org/api/v2/assets/anwPTnnhVoMGvFycsgpKYU/data/876592161/attachments/att69z3aoZPBcVLUyar2hRqq/ | LJ2: SA-PRT-2.4 | LK2: IMG_5505-21_38_43.jpeg | LL2: https://kf.kobotoolbox.org/api/v2/assets/anwPTnnhVoMGvFycsgpKYU/data/876592161/attachments/attGnovScS8mxCzpBu8HTZ7Q/ | LM2: SO-PRV-2.3 | LW2: 876592161 | LX2: 8cfef036-558c-4515-b5ac-7650ae3ffbfc | LY2: 46288.871 | MA2: submitted_via_web | MC2: vVAB5uRVrkn4ZncfRrvFBV | MD2: uuid:8cfef036-558c-4515-b5ac-7650ae3ffbfc | ME2: 2

Sheet SAISIE
A4: Code du chantier | B4: MAAC | D4: Cotés | E4: =COUNTIF($K$19:$K$149,"OK") -> 0
A5: Date de la visite | B5: 46283 | D5: Non applicables | E5: =COUNTIF($K$19:$K$149,"NA") -> 0
A6: Type d'ouvrage | B6: =IF($B$17=0,"",IFERROR(INDEX(IMP_DONNEES,$B$17,MATCH("type_ouvrage",IMP_ENTETES,0)),"")) | D6: Manquants | E6: =COUNTIF($K$19:$K$149,"Manquant") -> 0
A7: Phase d'avancement | B7: =IF($B$17=0,"",IFERROR(INDEX(IMP_DONNEES,$B$17,MATCH("phase",IMP_ENTETES,0)),"")) | D7: Anomalies | E7: =SUMPRODUCT(($K$19:$K$149<>"")*($K$19:$K$149<>"OK")*($K$19:$K$149<>"NA")*($K$19:$K$149<>"Manquant"))
A8: Effectif ouvrier présent | B8: =IF($B$17=0,"",IFERROR(INDEX(IMP_DONNEES,$B$17,MATCH("effectif_total",IMP_ENTETES,0)),"")) | D8: Total | E8: =E4+E5+E6+E7
A9: dont hommes | B9: =IF($B$17=0,"",IFERROR(INDEX(IMP_DONNEES,$B$17,MATCH("effectif_h",IMP_ENTETES,0)),""))
A10: dont femmes | B10: =IF($B$17=0,"",IFERROR(INDEX(IMP_DONNEES,$B$17,MATCH("effectif_f",IMP_ENTETES,0)),""))
A11: Entreprise éxécutante | B11: =IF($B$17=0,"",IFERROR(INDEX(IMP_DONNEES,$B$17,MATCH("entreprise",IMP_ENTETES,0)),""))
A12: Observateur | B12: =IF($B$17=0,"",IFERROR(INDEX(IMP_DONNEES,$B$17,MATCH("observateur",IMP_ENTETES,0)),""))
A13: Météo des 24 dernières heures | B13: =IF($B$17=0,"",IFERROR(INDEX(IMP_DONNEES,$B$17,MATCH("meteo_24h",IMP_ENTETES,0)),""))
A14: Heure de début | B14: =IF($B$17=0,"",IFERROR(INDEX(IMP_DONNEES,$B$17,MATCH("heure_debut",IMP_ENTETES,0)),""))
A15: Heure de fin | B15: =IF($B$17=0,"",IFERROR(INDEX(IMP_DONNEES,$B$17,MATCH("heure_fin",IMP_ENTETES,0)),""))
A16: Durée | B16: =IF(OR($B$14="",$B$15=""),"",TEXT(IFERROR(TIMEVALUE(LEFT($B$15,5)),$B$15)-IFERROR(TIMEVALUE(LEFT($B$14,5)),$B$14),"[h]:mm"))
A17: Ligne de la visite dans IMPORT | B17: =IF(OR($B$4="",$B$5=""),0,SUMPRODUCT((INDEX(OFFSET(IMPORT!$A$1,1,0,999,1000),0,MATCH("code_chantier",IMP_ENTETES,0))=$B$4)*(TEXT(INDEX(OFFSET(IMPORT!$A$1,1,0,999,1000),0,MATCH("date_visite",IMP_ENTETES,0)),"yyyy-mm-dd")=TEXT($B$5,"yyyy-mm-dd"))*ROW(OFFSET(IMPORT!$A$1,1,0,999,1))))
A18: CODE | B18: SOUS-INDICATEUR | C18: TYPE | D18: NA AUTORISE | E18: VALEUR IMPORTEE | F18: DENOMINATEUR IMPORTE | G18: VALEUR CORRIGEE | H18: DENOMINATEUR CORRIGE | I18: VALEUR RETENUE | J18: DENOMINATEUR RETENU | K18: CONTROLE | L18: OBSERVATION
A19: =REFERENTIEL!E4 -> SA-PRV-1.1 | B19: =REFERENTIEL!F4 -> Présence d'un moyen d'arrosage en état de fonctionner et affecté au chantier | C19: =REFERENTIEL!H4 -> Binaire | D19: =REFERENTIEL!I4 -> NON | E19: =IF($B$17=0,"",IF($C19<>"Taux",IFERROR(INDEX(IMP_DONNEES,$B$17,MATCH(REFERENTIEL!G4,IMP_ENTETES,0)),""),IF(IFERROR(INDEX(IMP_DONNEES,$B$17,MATCH(REFERENTIEL!G4&"_statut",IMP_ENTETES,0)),"")="N","NA",IFERROR(INDEX(IMP_DONNEES,$B$17,MATCH(REFERENTIEL!G4&"_num",IMP_ENTETES,0)),"")))) | F19: =IF($B$17=0,"",IF($C19<>"Taux","",IFERROR(INDEX(IMP_DONNEES,$B$17,MATCH(REFERENTIEL!G4&"_den",IMP_ENTETES,0)),""))) | I19: =IF($B$17=0,"",IF($G19<>"",IF($G19="NA","",$G19),IF(OR($E19="",$E19="NA"),"",IFERROR($E19*1,"")))) | J19: =IF($C19<>"Taux","",IF($H19<>"",$H19,IF($F19="","",IFERROR($F19*1,"")))) | K19: =IF($B$17=0,"",IF(OR($G19="NA",AND($G19="",$E19="NA")),IF($D19="OUI","NA","NA interdit"),IF($I19="","Manquant",IF($C19="Binaire",IF(OR($I19=0,$I19=1),"OK","Hors champ"),IF($C19="Maturité",IF(AND($I19>=1,$I19<=5,INT($I19)=$I19),"OK","Hors champ"),IF($I19<0,"Hors champ",IF(OR($J19="",NOT(ISNUMBER($J19)),$J19<=0),"Dén. invalide",IF($I19>$J19,"Num. > dén.","OK")))))))) | L19: =IF($B$17=0,"",IFERROR(INDEX(IMP_DONNEES,$B$17,MATCH(REFERENTIEL!G4&"_obs",IMP_ENTETES,0)),""))
A20: =REFERENTIEL!E5 -> SA-PRV-1.2 | B20: =REFERENTIEL!F5 -> Présence de bâches ou de couverture sur les stocks de matériaux fins | C20: =REFERENTIEL!H5 -> Binaire | D20: =REFERENTIEL!I5 -> OUI | E20: =IF($B$17=0,"",IF($C20<>"Taux",IFERROR(INDEX(IMP_DONNEES,$B$17,MATCH(REFERENTIEL!G5,IMP_ENTETES,0)),""),IF(IFERROR(INDEX(IMP_DONNEES,$B$17,MATCH(REFERENTIEL!G5&"_statut",IMP_ENTETES,0)),"")="N","NA",IFERROR(INDEX(IMP_DONNEES,$B$17,MATCH(REFERENTIEL!G5&"_num",IMP_ENTETES,0)),"")))) | F20: =IF($B$17=0,"",IF($C20<>"Taux","",IFERROR(INDEX(IMP_DONNEES,$B$17,MATCH(REFERENTIEL!G5&"_den",IMP_ENTETES,0)),""))) | I20: =IF($B$17=0,"",IF($G20<>"",IF($G20="NA","",$G20),IF(OR($E20="",$E20="NA"),"",IFERROR($E20*1,"")))) | J20: =IF($C20<>"Taux","",IF($H20<>"",$H20,IF($F20="","",IFERROR($F20*1,"")))) | K20: =IF($B$17=0,"",IF(OR($G20="NA",AND($G20="",$E20="NA")),IF($D20="OUI","NA","NA interdit"),IF($I20="","Manquant",IF($C20="Binaire",IF(OR($I20=0,$I20=1),"OK","Hors champ"),IF($C20="Maturité",IF(AND($I20>=1,$I20<=5,INT($I20)=$I20),"OK","Hors champ"),IF($I20<0,"Hors champ",IF(OR($J20="",NOT(ISNUMBER($J20)),$J20<=0),"Dén. invalide",IF($I20>$J20,"Num. > dén.","OK")))))))) | L20: =IF($B$17=0,"",IFERROR(INDEX(IMP_DONNEES,$B$17,MATCH(REFERENTIEL!G5&"_obs",IMP_ENTETES,0)),""))
A21: =REFERENTIEL!E6 -> SA-PRV-1.3 | B21: =REFERENTIEL!F6 -> Absence de nuage de poussière constaté au cours de la visite | C21: =REFERENTIEL!H6 -> Binaire | D21: =REFERENTIEL!I6 -> NON | E21: =IF($B$17=0,"",IF($C21<>"Taux",IFERROR(INDEX(IMP_DONNEES,$B$17,MATCH(REFERENTIEL!G6,IMP_ENTETES,0)),""),IF(IFERROR(INDEX(IMP_DONNEES,$B$17,MATCH(REFERENTIEL!G6&"_statut",IMP_ENTETES,0)),"")="N","NA",IFERROR(INDEX(IMP_DONNEES,$B$17,MATCH(REFERENTIEL!G6&"_num",IMP_ENTETES,0)),"")))) | F21: =IF($B$17=0,"",IF($C21<>"Taux","",IFERROR(INDEX(IMP_DONNEES,$B$17,MATCH(REFERENTIEL!G6&"_den",IMP_ENTETES,0)),""))) | I21: =IF($B$17=0,"",IF($G21<>"",IF($G21="NA","",$G21),IF(OR($E21="",$E21="NA"),"",IFERROR($E21*1,"")))) | J21: =IF($C21<>"Taux","",IF($H21<>"",$H21,IF($F21="","",IFERROR($F21*1,"")))) | K21: =IF($B$17=0,"",IF(OR($G21="NA",AND($G21="",$E21="NA")),IF($D21="OUI","NA","NA interdit"),IF($I21="","Manquant",IF($C21="Binaire",IF(OR($I21=0,$I21=1),"OK","Hors champ"),IF($C21="Maturité",IF(AND($I21>=1,$I21<=5,INT($I21)=$I21),"OK","Hors champ"),IF($I21<0,"Hors champ",IF(OR($J21="",NOT(ISNUMBER($J21)),$J21<=0),"Dén. invalide",IF($I21>$J21,"Num. > dén.","OK")))))))) | L21: =IF($B$17=0,"",IFERROR(INDEX(IMP_DONNEES,$B$17,MATCH(REFERENTIEL!G6&"_obs",IMP_ENTETES,0)),""))
A22: =REFERENTIEL!E7 -> SA-PRV-1.4 | B22: =REFERENTIEL!F7 -> Présence d’eau au poste de découpe humide | C22: =REFERENTIEL!H7 -> Binaire | D22: =REFERENTIEL!I7 -> OUI | E22: =IF($B$17=0,"",IF($C22<>"Taux",IFERROR(INDEX(IMP_DONNEES,$B$17,MATCH(REFERENTIEL!G7,IMP_ENTETES,0)),""),IF(IFERROR(INDEX(IMP_DONNEES,$B$17,MATCH(REFERENTIEL!G7&"_statut",IMP_ENTETES,0)),"")="N","NA",IFERROR(INDEX(IMP_DONNEES,$B$17,MATCH(REFERENTIEL!G7&"_num",IMP_ENTETES,0)),"")))) | F22: =IF($B$17=0,"",IF($C22<>"Taux","",IFERROR(INDEX(IMP_DONNEES,$B$17,MATCH(REFERENTIEL!G7&"_den",IMP_ENTETES,0)),""))) | I22: =IF($B$17=0,"",IF($G22<>"",IF($G22="NA","",$G22),IF(OR($E22="",$E22="NA"),"",IFERROR($E22*1,"")))) | J22: =IF($C22<>"Taux","",IF($H22<>"",$H22,IF($F22="","",IFERROR($F22*1,"")))) | K22: =IF($B$17=0,"",IF(OR($G22="NA",AND($G22="",$E22="NA")),IF($D22="OUI","NA","NA interdit"),IF($I22="","Manquant",IF($C22="Binaire",IF(OR($I22=0,$I22=1),"OK","Hors champ"),IF($C22="Maturité",IF(AND($I22>=1,$I22<=5,INT($I22)=$I22),"OK","Hors champ"),IF($I22<0,"Hors champ",IF(OR($J22="",NOT(ISNUMBER($J22)),$J22<=0),"Dén. invalide",IF($I22>$J22,"Num. > dén.","OK")))))))) | L22: =IF($B$17=0,"",IFERROR(INDEX(IMP_DONNEES,$B$17,MATCH(REFERENTIEL!G7&"_obs",IMP_ENTETES,0)),""))
A23: =REFERENTIEL!E8 -> SA-PRV-2.1 | B23: =REFERENTIEL!F8 -> Présence d'un planning de nettoyage du chantier | C23: =REFERENTIEL!H8 -> Binaire | D23: =REFERENTIEL!I8 -> NON | E23: =IF($B$17=0,"",IF($C23<>"Taux",IFERROR(INDEX(IMP_DONNEES,$B$17,MATCH(REFERENTIEL!G8,IMP_ENTETES,0)),""),IF(IFERROR(INDEX(IMP_DONNEES,$B$17,MATCH(REFERENTIEL!G8&"_statut",IMP_ENTETES,0)),"")="N","NA",IFERROR(INDEX(IMP_DONNEES,$B$17,MATCH(REFERENTIEL!G8&"_num",IMP_ENTETES,0)),"")))) | F23: =IF($B$17=0,"",IF($C23<>"Taux","",IFERROR(INDEX(IMP_DONNEES,$B$17,MATCH(REFERENTIEL!G8&"_den",IMP_ENTETES,0)),""))) | I23: =IF($B$17=0,"",IF($G23<>"",IF($G23="NA","",$G23),IF(OR($E23="",$E23="NA"),"",IFERROR($E23*1,"")))) | J23: =IF($C23<>"Taux","",IF($H23<>"",$H23,IF($F23="","",IFERROR($F23*1,"")))) | K23: =IF($B$17=0,"",IF(OR($G23="NA",AND($G23="",$E23="NA")),IF($D23="OUI","NA","NA interdit"),IF($I23="","Manquant",IF($C23="Binaire",IF(OR($I23=0,$I23=1),"OK","Hors champ"),IF($C23="Maturité",IF(AND($I23>=1,$I23<=5,INT($I23)=$I23),"OK","Hors champ"),IF($I23<0,"Hors champ",IF(OR($J23="",NOT(ISNUMBER($J23)),$J23<=0),"Dén. invalide",IF($I23>$J23,"Num. > dén.","OK")))))))) | L23: =IF($B$17=0,"",IFERROR(INDEX(IMP_DONNEES,$B$17,MATCH(REFERENTIEL!G8&"_obs",IMP_ENTETES,0)),""))
A24: =REFERENTIEL!E9 -> SA-PRV-2.2 | B24: =REFERENTIEL!F9 -> Absence de déchets alimentaires ou de restes de repas abandonnés sur l'emprise | C24: =REFERENTIEL!H9 -> Binaire | D24: =REFERENTIEL!I9 -> NON | E24: =IF($B$17=0,"",IF($C24<>"Taux",IFERROR(INDEX(IMP_DONNEES,$B$17,MATCH(REFERENTIEL!G9,IMP_ENTETES,0)),""),IF(IFERROR(INDEX(IMP_DONNEES,$B$17,MATCH(REFERENTIEL!G9&"_statut",IMP_ENTETES,0)),"")="N","NA",IFERROR(INDEX(IMP_DONNEES,$B$17,MATCH(REFERENTIEL!G9&"_num",IMP_ENTETES,0)),"")))) | F24: =IF($B$17=0,"",IF($C24<>"Taux","",IFERROR(INDEX(IMP_DONNEES,$B$17,MATCH(REFERENTIEL!G9&"_den",IMP_ENTETES,0)),""))) | I24: =IF($B$17=0,"",IF($G24<>"",IF($G24="NA","",$G24),IF(OR($E24="",$E24="NA"),"",IFERROR($E24*1,"")))) | J24: =IF($C24<>"Taux","",IF($H24<>"",$H24,IF($F24="","",IFERROR($F24*1,"")))) | K24: =IF($B$17=0,"",IF(OR($G24="NA",AND($G24="",$E24="NA")),IF($D24="OUI","NA","NA interdit"),IF($I24="","Manquant",IF($C24="Binaire",IF(OR($I24=0,$I24=1),"OK","Hors champ"),IF($C24="Maturité",IF(AND($I24>=1,$I24<=5,INT($I24)=$I24),"OK","Hors champ"),IF($I24<0,"Hors champ",IF(OR($J24="",NOT(ISNUMBER($J24)),$J24<=0),"Dén. invalide",IF($I24>$J24,"Num. > dén.","OK")))))))) | L24: =IF($B$17=0,"",IFERROR(INDEX(IMP_DONNEES,$B$17,MATCH(REFERENTIEL!G9&"_obs",IMP_ENTETES,0)),""))
A25: =REFERENTIEL!E10 -> SA-PRV-2.3 | B25: =REFERENTIEL!F10 -> Présence d'un drainage ou d'un écoulement entretenu évitant la stagnation d'eau | C25: =REFERENTIEL!H10 -> Binaire | D25: =REFERENTIEL!I10 -> NON | E25: =IF($B$17=0,"",IF($C25<>"Taux",IFERROR(INDEX(IMP_DONNEES,$B$17,MATCH(REFERENTIEL!G10,IMP_ENTETES,0)),""),IF(IFERROR(INDEX(IMP_DONNEES,$B$17,MATCH(REFERENTIEL!G10&"_statut",IMP_ENTETES,0)),"")="N","NA",IFERROR(INDEX(IMP_DONNEES,$B$17,MATCH(REFERENTIEL!G10&"_num",IMP_ENTETES,0)),"")))) | F25: =IF($B$17=0,"",IF($C25<>"Taux","",IFERROR(INDEX(IMP_DONNEES,$B$17,MATCH(REFERENTIEL!G10&"_den",IMP_ENTETES,0)),""))) | I25: =IF($B$17=0,"",IF($G25<>"",IF($G25="NA","",$G25),IF(OR($E25="",$E25="NA"),"",IFERROR($E25*1,"")))) | J25: =IF($C25<>"Taux","",IF($H25<>"",$H25,IF($F25="","",IFERROR($F25*1,"")))) | K25: =IF($B$17=0,"",IF(OR($G25="NA",AND($G25="",$E25="NA")),IF($D25="OUI","NA","NA interdit"),IF($I25="","Manquant",IF($C25="Binaire",IF(OR($I25=0,$I25=1),"OK","Hors champ"),IF($C25="Maturité",IF(AND($I25>=1,$I25<=5,INT($I25)=$I25),"OK","Hors champ"),IF($I25<0,"Hors champ",IF(OR($J25="",NOT(ISNUMBER($J25)),$J25<=0),"Dén. invalide",IF($I25>$J25,"Num. > dén.","OK")))))))) | L25: =IF($B$17=0,"",IFERROR(INDEX(IMP_DONNEES,$B$17,MATCH(REFERENTIEL!G10&"_obs",IMP_ENTETES,0)),""))
A26: =REFERENTIEL!E11 -> SA-PRV-2.4 | B26: =REFERENTIEL!F11 -> Absence de récipients, pneus ou débris retenant l'eau sur l'emprise | C26: =REFERENTIEL!H11 -> Binaire | D26: =REFERENTIEL!I11 -> NON | E26: =IF($B$17=0,"",IF($C26<>"Taux",IFERROR(INDEX(IMP_DONNEES,$B$17,MATCH(REFERENTIEL!G11,IMP_ENTETES,0)),""),IF(IFERROR(INDEX(IMP_DONNEES,$B$17,MATCH(REFERENTIEL!G11&"_statut",IMP_ENTETES,0)),"")="N","NA",IFERROR(INDEX(IMP_DONNEES,$B$17,MATCH(REFERENTIEL!G11&"_num",IMP_ENTETES,0)),"")))) | F26: =IF($B$17=0,"",IF($C26<>"Taux","",IFERROR(INDEX(IMP_DONNEES,$B$17,MATCH(REFERENTIEL!G11&"_den",IMP_ENTETES,0)),""))) | I26: =IF($B$17=0,"",IF($G26<>"",IF($G26="NA","",$G26),IF(OR($E26="",$E26="NA"),"",IFERROR($E26*1,"")))) | J26: =IF($C26<>"Taux","",IF($H26<>"",$H26,IF($F26="","",IFERROR($F26*1,"")))) | K26: =IF($B$17=0,"",IF(OR($G26="NA",AND($G26="",$E26="NA")),IF($D26="OUI","NA","NA interdit"),IF($I26="","Manquant",IF($C26="Binaire",IF(OR($I26=0,$I26=1),"OK","Hors champ"),IF($C26="Maturité",IF(AND($I26>=1,$I26<=5,INT($I26)=$I26),"OK","Hors champ"),IF($I26<0,"Hors champ",IF(OR($J26="",NOT(ISNUMBER($J26)),$J26<=0),"Dén. invalide",IF($I26>$J26,"Num. > dén.","OK")))))))) | L26: =IF($B$17=0,"",IFERROR(INDEX(IMP_DONNEES,$B$17,MATCH(REFERENTIEL!G11&"_obs",IMP_ENTETES,0)),""))
A27: =REFERENTIEL!E12 -> SA-PRV-3.1 | B27: =REFERENTIEL!F12 -> Tenue d'un registre des séances de sensibilisation aux risques sanitaires | C27: =REFERENTIEL!H12 -> Binaire | D27: =REFERENTIEL!I12 -> NON | E27: =IF($B$17=0,"",IF($C27<>"Taux",IFERROR(INDEX(IMP_DONNEES,$B$17,MATCH(REFERENTIEL!G12,IMP_ENTETES,0)),""),IF(IFERROR(INDEX(IMP_DONNEES,$B$17,MATCH(REFERENTIEL!G12&"_statut",IMP_ENTETES,0)),"")="N","NA",IFERROR(INDEX(IMP_DONNEES,$B$17,MATCH(REFERENTIEL!G12&"_num",IMP_ENTETES,0)),"")))) | F27: =IF($B$17=0,"",IF($C27<>"Taux","",IFERROR(INDEX(IMP_DONNEES,$B$17,MATCH(REFERENTIEL!G12&"_den",IMP_ENTETES,0)),""))) | I27: =IF($B$17=0,"",IF($G27<>"",IF($G27="NA","",$G27),IF(OR($E27="",$E27="NA"),"",IFERROR($E27*1,"")))) | J27: =IF($C27<>"Taux","",IF($H27<>"",$H27,IF($F27="","",IFERROR($F27*1,"")))) | K27: =IF($B$17=0,"",IF(OR($G27="NA",AND($G27="",$E27="NA")),IF($D27="OUI","NA","NA interdit"),IF($I27="","Manquant",IF($C27="Binaire",IF(OR($I27=0,$I27=1),"OK","Hors champ"),IF($C27="Maturité",IF(AND($I27>=1,$I27<=5,INT($I27)=$I27),"OK","Hors champ"),IF($I27<0,"Hors champ",IF(OR($J27="",NOT(ISNUMBER($J27)),$J27<=0),"Dén. invalide",IF($I27>$J27,"Num. > dén.","OK")))))))) | L27: =IF($B$17=0,"",IFERROR(INDEX(IMP_DONNEES,$B$17,MATCH(REFERENTIEL!G12&"_obs",IMP_ENTETES,0)),""))
A28: =REFERENTIEL!E13 -> SA-PRV-3.2 | B28: =REFERENTIEL!F13 -> Présence d'un responsable HSE désigné sur le chantier | C28: =REFERENTIEL!H13 -> Binaire | D28: =REFERENTIEL!I13 -> NON | E28: =IF($B$17=0,"",IF($C28<>"Taux",IFERROR(INDEX(IMP_DONNEES,$B$17,MATCH(REFERENTIEL!G13,IMP_ENTETES,0)),""),IF(IFERROR(INDEX(IMP_DONNEES,$B$17,MATCH(REFERENTIEL!G13&"_statut",IMP_ENTETES,0)),"")="N","NA",IFERROR(INDEX(IMP_DONNEES,$B$17,MATCH(REFERENTIEL!G13&"_num",IMP_ENTETES,0)),"")))) | F28: =IF($B$17=0,"",IF($C28<>"Taux","",IFERROR(INDEX(IMP_DONNEES,$B$17,MATCH(REFERENTIEL!G13&"_den",IMP_ENTETES,0)),""))) | I28: =IF($B$17=0,"",IF($G28<>"",IF($G28="NA","",$G28),IF(OR($E28="",$E28="NA"),"",IFERROR($E28*1,"")))) | J28: =IF($C28<>"Taux","",IF($H28<>"",$H28,IF($F28="","",IFERROR($F28*1,"")))) | K28: =IF($B$17=0,"",IF(OR($G28="NA",AND($G28="",$E28="NA")),IF($D28="OUI","NA","NA interdit"),IF($I28="","Manquant",IF($C28="Binaire",IF(OR($I28=0,$I28=1),"OK","Hors champ"),IF($C28="Maturité",IF(AND($I28>=1,$I28<=5,INT($I28)=$I28),"OK","Hors champ"),IF($I28<0,"Hors champ",IF(OR($J28="",NOT(ISNUMBER($J28)),$J28<=0),"Dén. invalide",IF($I28>$J28,"Num. > dén.","OK")))))))) | L28: =IF($B$17=0,"",IFERROR(INDEX(IMP_DONNEES,$B$17,MATCH(REFERENTIEL!G13&"_obs",IMP_ENTETES,0)),""))
A29: =REFERENTIEL!E14 -> SA-PRV-3.3 | B29: =REFERENTIEL!F14 -> Taux de travailleurs ayant reçu une induction sur les risques sanitaires | C29: =REFERENTIEL!H14 -> Taux | D29: =REFERENTIEL!I14 -> NON | E29: =IF($B$17=0,"",IF($C29<>"Taux",IFERROR(INDEX(IMP_DONNEES,$B$17,MATCH(REFERENTIEL!G14,IMP_ENTETES,0)),""),IF(IFERROR(INDEX(IMP_DONNEES,$B$17,MATCH(REFERENTIEL!G14&"_statut",IMP_ENTETES,0)),"")="N","NA",IFERROR(INDEX(IMP_DONNEES,$B$17,MATCH(REFERENTIEL!G14&"_num",IMP_ENTETES,0)),"")))) | F29: =IF($B$17=0,"",IF($C29<>"Taux","",IFERROR(INDEX(IMP_DONNEES,$B$17,MATCH(REFERENTIEL!G14&"_den",IMP_ENTETES,0)),""))) | I29: =IF($B$17=0,"",IF($G29<>"",IF($G29="NA","",$G29),IF(OR($E29="",$E29="NA"),"",IFERROR($E29*1,"")))) | J29: =IF($C29<>"Taux","",IF($H29<>"",$H29,IF($F29="","",IFERROR($F29*1,"")))) | K29: =IF($B$17=0,"",IF(OR($G29="NA",AND($G29="",$E29="NA")),IF($D29="OUI","NA","NA interdit"),IF($I29="","Manquant",IF($C29="Binaire",IF(OR($I29=0,$I29=1),"OK","Hors champ"),IF($C29="Maturité",IF(AND($I29>=1,$I29<=5,INT($I29)=$I29),"OK","Hors champ"),IF($I29<0,"Hors champ",IF(OR($J29="",NOT(ISNUMBER($J29)),$J29<=0),"Dén. invalide",IF($I29>$J29,"Num. > dén.","OK")))))))) | L29: =IF($B$17=0,"",IFERROR(INDEX(IMP_DONNEES,$B$17,MATCH(REFERENTIEL!G14&"_obs",IMP_ENTETES,0)),""))
A30: =REFERENTIEL!E15 -> SA-PRV-3.4 | B30: =REFERENTIEL!F15 -> Présence d'affiches sur les règles d'hygiène du chantier | C30: =REFERENTIEL!H15 -> Binaire | D30: =REFERENTIEL!I15 -> NON | E30: =IF($B$17=0,"",IF($C30<>"Taux",IFERROR(INDEX(IMP_DONNEES,$B$17,MATCH(REFERENTIEL!G15,IMP_ENTETES,0)),""),IF(IFERROR(INDEX(IMP_DONNEES,$B$17,MATCH(REFERENTIEL!G15&"_statut",IMP_ENTETES,0)),"")="N","NA",IFERROR(INDEX(IMP_DONNEES,$B$17,MATCH(REFERENTIEL!G15&"_num",IMP_ENTETES,0)),"")))) | F30: =IF($B$17=0,"",IF($C30<>"Taux","",IFERROR(INDEX(IMP_DONNEES,$B$17,MATCH(REFERENTIEL!G15&"_den",IMP_ENTETES,0)),""))) | I30: =IF($B$17=0,"",IF($G30<>"",IF($G30="NA","",$G30),IF(OR($E30="",$E30="NA"),"",IFERROR($E30*1,"")))) | J30: =IF($C30<>"Taux","",IF($H30<>"",$H30,IF($F30="","",IFERROR($F30*1,"")))) | K30: =IF($B$17=0,"",IF(OR($G30="NA",AND($G30="",$E30="NA")),IF($D30="OUI","NA","NA interdit"),IF($I30="","Manquant",IF($C30="Binaire",IF(OR($I30=0,$I30=1),"OK","Hors champ"),IF($C30="Maturité",IF(AND($I30>=1,$I30<=5,INT($I30)=$I30),"OK","Hors champ"),IF($I30<0,"Hors champ",IF(OR($J30="",NOT(ISNUMBER($J30)),$J30<=0),"Dén. invalide",IF($I30>$J30,"Num. > dén.","OK")))))))) | L30: =IF($B$17=0,"",IFERROR(INDEX(IMP_DONNEES,$B$17,MATCH(REFERENTIEL!G15&"_obs",IMP_ENTETES,0)),""))
... A149: =REFERENTIEL!E134 -> SO-CNF-3.4 | B149: =REFERENTIEL!F134 -> Présence d’une trace de suite donnée aux écarts sociaux relevés lors des missions de contrôle | C149: =REFERENTIEL!H134 -> Binaire | D149: =REFERENTIEL!I134 -> OUI | E149: =IF($B$17=0,"",IF($C149<>"Taux",IFERROR(INDEX(IMP_DONNEES,$B$17,MATCH(REFERENTIEL!G134,IMP_ENTETES,0)),""),IF(IFERROR(INDEX(IMP_DONNEES,$B$17,MATCH(REFERENTIEL!G134&"_statut",IMP_ENTETES,0)),"")="N","NA",IFERROR(INDEX(IMP_DONNEES,$B$17,MATCH(REFERENTIEL!G134&"_num",IMP_ENTETES,0)),"")))) | F149: =IF($B$17=0,"",IF($C149<>"Taux","",IFERROR(INDEX(IMP_DONNEES,$B$17,MATCH(REFERENTIEL!G134&"_den",IMP_ENTETES,0)),""))) | I149: =IF($B$17=0,"",IF($G149<>"",IF($G149="NA","",$G149),IF(OR($E149="",$E149="NA"),"",IFERROR($E149*1,"")))) | J149: =IF($C149<>"Taux","",IF($H149<>"",$H149,IF($F149="","",IFERROR($F149*1,"")))) | K149: =IF($B$17=0,"",IF(OR($G149="NA",AND($G149="",$E149="NA")),IF($D149="OUI","NA","NA interdit"),IF($I149="","Manquant",IF($C149="Binaire",IF(OR($I149=0,$I149=1),"OK","Hors champ"),IF($C149="Maturité",IF(AND($I149>=1,$I149<=5,INT($I149)=$I149),"OK","Hors champ"),IF($I149<0,"Hors champ",IF(OR($J149="",NOT(ISNUMBER($J149)),$J149<=0),"Dén. invalide",IF($I149>$J149,"Num. > dén.","OK")))))))) | L149: =IF($B$17=0,"",IFERROR(INDEX(IMP_DONNEES,$B$17,MATCH(REFERENTIEL!G134&"_obs",IMP_ENTETES,0)),""))

Sheet CALCUL
A1: Calcul- Normalisation et Agrégation | AE1: Seuil des sous indicateurs faibles | AF1: 50
A3: Code | B3: Dimension | C3: Parametre | D3: Code Indicateur | E3: Type | F3: Facteur | G3: Score normalisé | H3: Alerte | I3: NA | J3: Non coté | L3: Code Indicateur | M3: Dimension | N3: Parametre | O3: Score Indicateur | P3: Retiré | R3: Dimension | S3: Parametre | T3: Score Parametre | U3: Indicateurs | W3: Dimension | X3: Indice | Y3: Niveau | Z3: NA | AA3: Non cotés | AB3: Alertes | AC3: Indicateurs retirés | AE3: Rang Alerte | AF3: Rang Faible
A4: =REFERENTIEL!E4 -> SA-PRV-1.1 | B4: =REFERENTIEL!A4 -> Santé | C4: =REFERENTIEL!B4 -> Prévention | D4: =REFERENTIEL!C4 -> SA-PRV-1 | E4: =REFERENTIEL!H4 -> Binaire | F4: =REFERENTIEL!J4 -> 1 | G4: =IF(SAISIE!$I19="","",IF($E4="Binaire",SAISIE!$I19*100,IF($E4="Maturité",(SAISIE!$I19-1)*25,IF(OR(SAISIE!$J19="",SAISIE!$J19=0),"",MIN(100,SAISIE!$I19*$F4/SAISIE!$J19*100))))) | H4: =IF(AND($G4<>"",$G4=0),1,"") | I4: =IF(SAISIE!$K19="NA",1,"") | J4: =IF(AND(SAISIE!$K19<>"",SAISIE!$K19<>"OK",SAISIE!$K19<>"NA"),1,"") | L4: =$D$4 -> SA-PRV-1 | M4: =IFERROR(INDEX($B$4:$B$134,MATCH($L4,$D$4:$D$134,0)),"") -> Santé | N4: =IFERROR(INDEX($C$4:$C$134,MATCH($L4,$D$4:$D$134,0)),"") -> Prévention | O4: =IF($L4="","",IFERROR(AVERAGEIF($D$4:$D$134,$L4,$G$4:$G$134),"")) | P4: =IF($L4="","",IF(COUNTIF($D$4:$D$134,$L4)=SUMIF($D$4:$D$134,$L4,$I$4:$I$134),1,"")) | R4: Santé | S4: Prévention | T4: =IFERROR(AVERAGEIFS($O$4:$O$36,$M$4:$M$36,$R4,$N$4:$N$36,$S4),"") | U4: =COUNTIFS($M$4:$M$36,$R4,$N$4:$N$36,$S4) -> 3 | W4: Santé | X4: =IFERROR(AVERAGEIF($R$4:$R$15,$W4,$T$4:$T$15),"") | Y4: =IF($X4="","",IF(ROUND($X4,2)<20,"Initial",IF(ROUND($X4,2)<40,"Basique",IF(ROUND($X4,2)<60,"Défini",IF(ROUND($X4,2)<80,"Maîtrisé","Optimisé"))))) | Z4: =SUMIF($B$4:$B$134,$W4,$I$4:$I$134) | AA4: =SUMIF($B$4:$B$134,$W4,$J$4:$J$134) | AB4: =SUMIF($B$4:$B$134,$W4,$H$4:$H$134) | AC4: =SUMIF($M$4:$M$36,$W4,$P$4:$P$36) | AE4: =IF($H4=1,COUNTIF($H$4:$H4,1),"") | AF4: =IF(AND($G4<>"",$G4>0,$G4<$AF$1),COUNTIFS($G$4:$G4,">0",$G$4:$G4,"<"&$AF$1),"")
A5: =REFERENTIEL!E5 -> SA-PRV-1.2 | B5: =REFERENTIEL!A5 -> Santé | C5: =REFERENTIEL!B5 -> Prévention | D5: =REFERENTIEL!C5 -> SA-PRV-1 | E5: =REFERENTIEL!H5 -> Binaire | F5: =REFERENTIEL!J5 -> 1 | G5: =IF(SAISIE!$I20="","",IF($E5="Binaire",SAISIE!$I20*100,IF($E5="Maturité",(SAISIE!$I20-1)*25,IF(OR(SAISIE!$J20="",SAISIE!$J20=0),"",MIN(100,SAISIE!$I20*$F5/SAISIE!$J20*100))))) | H5: =IF(AND($G5<>"",$G5=0),1,"") | I5: =IF(SAISIE!$K20="NA",1,"") | J5: =IF(AND(SAISIE!$K20<>"",SAISIE!$K20<>"OK",SAISIE!$K20<>"NA"),1,"") | L5: =IFERROR(INDEX($D$4:$D$134,MATCH($L4,$D$4:$D$134,0)+COUNTIF($D$4:$D$134,$L4)),"") -> SA-PRV-2 | M5: =IFERROR(INDEX($B$4:$B$134,MATCH($L5,$D$4:$D$134,0)),"") -> Santé | N5: =IFERROR(INDEX($C$4:$C$134,MATCH($L5,$D$4:$D$134,0)),"") -> Prévention | O5: =IF($L5="","",IFERROR(AVERAGEIF($D$4:$D$134,$L5,$G$4:$G$134),"")) | P5: =IF($L5="","",IF(COUNTIF($D$4:$D$134,$L5)=SUMIF($D$4:$D$134,$L5,$I$4:$I$134),1,"")) | R5: Santé | S5: Protection | T5: =IFERROR(AVERAGEIFS($O$4:$O$36,$M$4:$M$36,$R5,$N$4:$N$36,$S5),"") | U5: =COUNTIFS($M$4:$M$36,$R5,$N$4:$N$36,$S5) -> 2 | W5: Sécurité | X5: =IFERROR(AVERAGEIF($R$4:$R$15,$W5,$T$4:$T$15),"") | Y5: =IF($X5="","",IF(ROUND($X5,2)<20,"Initial",IF(ROUND($X5,2)<40,"Basique",IF(ROUND($X5,2)<60,"Défini",IF(ROUND($X5,2)<80,"Maîtrisé","Optimisé"))))) | Z5: =SUMIF($B$4:$B$134,$W5,$I$4:$I$134) | AA5: =SUMIF($B$4:$B$134,$W5,$J$4:$J$134) | AB5: =SUMIF($B$4:$B$134,$W5,$H$4:$H$134) | AC5: =SUMIF($M$4:$M$36,$W5,$P$4:$P$36) | AE5: =IF($H5=1,COUNTIF($H$4:$H5,1),"") | AF5: =IF(AND($G5<>"",$G5>0,$G5<$AF$1),COUNTIFS($G$4:$G5,">0",$G$4:$G5,"<"&$AF$1),"")
A6: =REFERENTIEL!E6 -> SA-PRV-1.3 | B6: =REFERENTIEL!A6 -> Santé | C6: =REFERENTIEL!B6 -> Prévention | D6: =REFERENTIEL!C6 -> SA-PRV-1 | E6: =REFERENTIEL!H6 -> Binaire | F6: =REFERENTIEL!J6 -> 1 | G6: =IF(SAISIE!$I21="","",IF($E6="Binaire",SAISIE!$I21*100,IF($E6="Maturité",(SAISIE!$I21-1)*25,IF(OR(SAISIE!$J21="",SAISIE!$J21=0),"",MIN(100,SAISIE!$I21*$F6/SAISIE!$J21*100))))) | H6: =IF(AND($G6<>"",$G6=0),1,"") | I6: =IF(SAISIE!$K21="NA",1,"") | J6: =IF(AND(SAISIE!$K21<>"",SAISIE!$K21<>"OK",SAISIE!$K21<>"NA"),1,"") | L6: =IFERROR(INDEX($D$4:$D$134,MATCH($L5,$D$4:$D$134,0)+COUNTIF($D$4:$D$134,$L5)),"") -> SA-PRV-3 | M6: =IFERROR(INDEX($B$4:$B$134,MATCH($L6,$D$4:$D$134,0)),"") -> Santé | N6: =IFERROR(INDEX($C$4:$C$134,MATCH($L6,$D$4:$D$134,0)),"") -> Prévention | O6: =IF($L6="","",IFERROR(AVERAGEIF($D$4:$D$134,$L6,$G$4:$G$134),"")) | P6: =IF($L6="","",IF(COUNTIF($D$4:$D$134,$L6)=SUMIF($D$4:$D$134,$L6,$I$4:$I$134),1,"")) | R6: Santé | S6: Conformité | T6: =IFERROR(AVERAGEIFS($O$4:$O$36,$M$4:$M$36,$R6,$N$4:$N$36,$S6),"") | U6: =COUNTIFS($M$4:$M$36,$R6,$N$4:$N$36,$S6) -> 3 | W6: Environnement | X6: =IFERROR(AVERAGEIF($R$4:$R$15,$W6,$T$4:$T$15),"") | Y6: =IF($X6="","",IF(ROUND($X6,2)<20,"Initial",IF(ROUND($X6,2)<40,"Basique",IF(ROUND($X6,2)<60,"Défini",IF(ROUND($X6,2)<80,"Maîtrisé","Optimisé"))))) | Z6: =SUMIF($B$4:$B$134,$W6,$I$4:$I$134) | AA6: =SUMIF($B$4:$B$134,$W6,$J$4:$J$134) | AB6: =SUMIF($B$4:$B$134,$W6,$H$4:$H$134) | AC6: =SUMIF($M$4:$M$36,$W6,$P$4:$P$36) | AE6: =IF($H6=1,COUNTIF($H$4:$H6,1),"") | AF6: =IF(AND($G6<>"",$G6>0,$G6<$AF$1),COUNTIFS($G$4:$G6,">0",$G$4:$G6,"<"&$AF$1),"")
A7: =REFERENTIEL!E7 -> SA-PRV-1.4 | B7: =REFERENTIEL!A7 -> Santé | C7: =REFERENTIEL!B7 -> Prévention | D7: =REFERENTIEL!C7 -> SA-PRV-1 | E7: =REFERENTIEL!H7 -> Binaire | F7: =REFERENTIEL!J7 -> 1 | G7: =IF(SAISIE!$I22="","",IF($E7="Binaire",SAISIE!$I22*100,IF($E7="Maturité",(SAISIE!$I22-1)*25,IF(OR(SAISIE!$J22="",SAISIE!$J22=0),"",MIN(100,SAISIE!$I22*$F7/SAISIE!$J22*100))))) | H7: =IF(AND($G7<>"",$G7=0),1,"") | I7: =IF(SAISIE!$K22="NA",1,"") | J7: =IF(AND(SAISIE!$K22<>"",SAISIE!$K22<>"OK",SAISIE!$K22<>"NA"),1,"") | L7: =IFERROR(INDEX($D$4:$D$134,MATCH($L6,$D$4:$D$134,0)+COUNTIF($D$4:$D$134,$L6)),"") -> SA-PRT-1 | M7: =IFERROR(INDEX($B$4:$B$134,MATCH($L7,$D$4:$D$134,0)),"") -> Santé | N7: =IFERROR(INDEX($C$4:$C$134,MATCH($L7,$D$4:$D$134,0)),"") -> Protection | O7: =IF($L7="","",IFERROR(AVERAGEIF($D$4:$D$134,$L7,$G$4:$G$134),"")) | P7: =IF($L7="","",IF(COUNTIF($D$4:$D$134,$L7)=SUMIF($D$4:$D$134,$L7,$I$4:$I$134),1,"")) | R7: Sécurité | S7: Prévention | T7: =IFERROR(AVERAGEIFS($O$4:$O$36,$M$4:$M$36,$R7,$N$4:$N$36,$S7),"") | U7: =COUNTIFS($M$4:$M$36,$R7,$N$4:$N$36,$S7) -> 3 | W7: Social | X7: =IFERROR(AVERAGEIF($R$4:$R$15,$W7,$T$4:$T$15),"") | Y7: =IF($X7="","",IF(ROUND($X7,2)<20,"Initial",IF(ROUND($X7,2)<40,"Basique",IF(ROUND($X7,2)<60,"Défini",IF(ROUND($X7,2)<80,"Maîtrisé","Optimisé"))))) | Z7: =SUMIF($B$4:$B$134,$W7,$I$4:$I$134) | AA7: =SUMIF($B$4:$B$134,$W7,$J$4:$J$134) | AB7: =SUMIF($B$4:$B$134,$W7,$H$4:$H$134) | AC7: =SUMIF($M$4:$M$36,$W7,$P$4:$P$36) | AE7: =IF($H7=1,COUNTIF($H$4:$H7,1),"") | AF7: =IF(AND($G7<>"",$G7>0,$G7<$AF$1),COUNTIFS($G$4:$G7,">0",$G$4:$G7,"<"&$AF$1),"")
A8: =REFERENTIEL!E8 -> SA-PRV-2.1 | B8: =REFERENTIEL!A8 -> Santé | C8: =REFERENTIEL!B8 -> Prévention | D8: =REFERENTIEL!C8 -> SA-PRV-2 | E8: =REFERENTIEL!H8 -> Binaire | F8: =REFERENTIEL!J8 -> 1 | G8: =IF(SAISIE!$I23="","",IF($E8="Binaire",SAISIE!$I23*100,IF($E8="Maturité",(SAISIE!$I23-1)*25,IF(OR(SAISIE!$J23="",SAISIE!$J23=0),"",MIN(100,SAISIE!$I23*$F8/SAISIE!$J23*100))))) | H8: =IF(AND($G8<>"",$G8=0),1,"") | I8: =IF(SAISIE!$K23="NA",1,"") | J8: =IF(AND(SAISIE!$K23<>"",SAISIE!$K23<>"OK",SAISIE!$K23<>"NA"),1,"") | L8: =IFERROR(INDEX($D$4:$D$134,MATCH($L7,$D$4:$D$134,0)+COUNTIF($D$4:$D$134,$L7)),"") -> SA-PRT-2 | M8: =IFERROR(INDEX($B$4:$B$134,MATCH($L8,$D$4:$D$134,0)),"") -> Santé | N8: =IFERROR(INDEX($C$4:$C$134,MATCH($L8,$D$4:$D$134,0)),"") -> Protection | O8: =IF($L8="","",IFERROR(AVERAGEIF($D$4:$D$134,$L8,$G$4:$G$134),"")) | P8: =IF($L8="","",IF(COUNTIF($D$4:$D$134,$L8)=SUMIF($D$4:$D$134,$L8,$I$4:$I$134),1,"")) | R8: Sécurité | S8: Protection | T8: =IFERROR(AVERAGEIFS($O$4:$O$36,$M$4:$M$36,$R8,$N$4:$N$36,$S8),"") | U8: =COUNTIFS($M$4:$M$36,$R8,$N$4:$N$36,$S8) -> 3 | AE8: =IF($H8=1,COUNTIF($H$4:$H8,1),"") | AF8: =IF(AND($G8<>"",$G8>0,$G8<$AF$1),COUNTIFS($G$4:$G8,">0",$G$4:$G8,"<"&$AF$1),"")
A9: =REFERENTIEL!E9 -> SA-PRV-2.2 | B9: =REFERENTIEL!A9 -> Santé | C9: =REFERENTIEL!B9 -> Prévention | D9: =REFERENTIEL!C9 -> SA-PRV-2 | E9: =REFERENTIEL!H9 -> Binaire | F9: =REFERENTIEL!J9 -> 1 | G9: =IF(SAISIE!$I24="","",IF($E9="Binaire",SAISIE!$I24*100,IF($E9="Maturité",(SAISIE!$I24-1)*25,IF(OR(SAISIE!$J24="",SAISIE!$J24=0),"",MIN(100,SAISIE!$I24*$F9/SAISIE!$J24*100))))) | H9: =IF(AND($G9<>"",$G9=0),1,"") | I9: =IF(SAISIE!$K24="NA",1,"") | J9: =IF(AND(SAISIE!$K24<>"",SAISIE!$K24<>"OK",SAISIE!$K24<>"NA"),1,"") | L9: =IFERROR(INDEX($D$4:$D$134,MATCH($L8,$D$4:$D$134,0)+COUNTIF($D$4:$D$134,$L8)),"") -> SA-CNF-1 | M9: =IFERROR(INDEX($B$4:$B$134,MATCH($L9,$D$4:$D$134,0)),"") -> Santé | N9: =IFERROR(INDEX($C$4:$C$134,MATCH($L9,$D$4:$D$134,0)),"") -> Conformité | O9: =IF($L9="","",IFERROR(AVERAGEIF($D$4:$D$134,$L9,$G$4:$G$134),"")) | P9: =IF($L9="","",IF(COUNTIF($D$4:$D$134,$L9)=SUMIF($D$4:$D$134,$L9,$I$4:$I$134),1,"")) | R9: Sécurité | S9: Conformité | T9: =IFERROR(AVERAGEIFS($O$4:$O$36,$M$4:$M$36,$R9,$N$4:$N$36,$S9),"") | U9: =COUNTIFS($M$4:$M$36,$R9,$N$4:$N$36,$S9) -> 3 | W9: TOTAL | Z9: =SUM(Z4:Z7) | AA9: =SUM(AA4:AA7) | AB9: =SUM(AB4:AB7) | AC9: =SUM(AC4:AC7) | AE9: =IF($H9=1,COUNTIF($H$4:$H9,1),"") | AF9: =IF(AND($G9<>"",$G9>0,$G9<$AF$1),COUNTIFS($G$4:$G9,">0",$G$4:$G9,"<"&$AF$1),"")
A10: =REFERENTIEL!E10 -> SA-PRV-2.3 | B10: =REFERENTIEL!A10 -> Santé | C10: =REFERENTIEL!B10 -> Prévention | D10: =REFERENTIEL!C10 -> SA-PRV-2 | E10: =REFERENTIEL!H10 -> Binaire | F10: =REFERENTIEL!J10 -> 1 | G10: =IF(SAISIE!$I25="","",IF($E10="Binaire",SAISIE!$I25*100,IF($E10="Maturité",(SAISIE!$I25-1)*25,IF(OR(SAISIE!$J25="",SAISIE!$J25=0),"",MIN(100,SAISIE!$I25*$F10/SAISIE!$J25*100))))) | H10: =IF(AND($G10<>"",$G10=0),1,"") | I10: =IF(SAISIE!$K25="NA",1,"") | J10: =IF(AND(SAISIE!$K25<>"",SAISIE!$K25<>"OK",SAISIE!$K25<>"NA"),1,"") | L10: =IFERROR(INDEX($D$4:$D$134,MATCH($L9,$D$4:$D$134,0)+COUNTIF($D$4:$D$134,$L9)),"") -> SA-CNF-2 | M10: =IFERROR(INDEX($B$4:$B$134,MATCH($L10,$D$4:$D$134,0)),"") -> Santé | N10: =IFERROR(INDEX($C$4:$C$134,MATCH($L10,$D$4:$D$134,0)),"") -> Conformité | O10: =IF($L10="","",IFERROR(AVERAGEIF($D$4:$D$134,$L10,$G$4:$G$134),"")) | P10: =IF($L10="","",IF(COUNTIF($D$4:$D$134,$L10)=SUMIF($D$4:$D$134,$L10,$I$4:$I$134),1,"")) | R10: Environnement | S10: Prévention | T10: =IFERROR(AVERAGEIFS($O$4:$O$36,$M$4:$M$36,$R10,$N$4:$N$36,$S10),"") | U10: =COUNTIFS($M$4:$M$36,$R10,$N$4:$N$36,$S10) -> 3 | W10: CONTRÔLE | X10: =COUNT($G$4:$G$134)+Z9+AA9 | AE10: =IF($H10=1,COUNTIF($H$4:$H10,1),"") | AF10: =IF(AND($G10<>"",$G10>0,$G10<$AF$1),COUNTIFS($G$4:$G10,">0",$G$4:$G10,"<"&$AF$1),"")
A11: =REFERENTIEL!E11 -> SA-PRV-2.4 | B11: =REFERENTIEL!A11 -> Santé | C11: =REFERENTIEL!B11 -> Prévention | D11: =REFERENTIEL!C11 -> SA-PRV-2 | E11: =REFERENTIEL!H11 -> Binaire | F11: =REFERENTIEL!J11 -> 1 | G11: =IF(SAISIE!$I26="","",IF($E11="Binaire",SAISIE!$I26*100,IF($E11="Maturité",(SAISIE!$I26-1)*25,IF(OR(SAISIE!$J26="",SAISIE!$J26=0),"",MIN(100,SAISIE!$I26*$F11/SAISIE!$J26*100))))) | H11: =IF(AND($G11<>"",$G11=0),1,"") | I11: =IF(SAISIE!$K26="NA",1,"") | J11: =IF(AND(SAISIE!$K26<>"",SAISIE!$K26<>"OK",SAISIE!$K26<>"NA"),1,"") | L11: =IFERROR(INDEX($D$4:$D$134,MATCH($L10,$D$4:$D$134,0)+COUNTIF($D$4:$D$134,$L10)),"") -> SA-CNF-3 | M11: =IFERROR(INDEX($B$4:$B$134,MATCH($L11,$D$4:$D$134,0)),"") -> Santé | N11: =IFERROR(INDEX($C$4:$C$134,MATCH($L11,$D$4:$D$134,0)),"") -> Conformité | O11: =IF($L11="","",IFERROR(AVERAGEIF($D$4:$D$134,$L11,$G$4:$G$134),"")) | P11: =IF($L11="","",IF(COUNTIF($D$4:$D$134,$L11)=SUMIF($D$4:$D$134,$L11,$I$4:$I$134),1,"")) | R11: Environnement | S11: Protection | T11: =IFERROR(AVERAGEIFS($O$4:$O$36,$M$4:$M$36,$R11,$N$4:$N$36,$S11),"") | U11: =COUNTIFS($M$4:$M$36,$R11,$N$4:$N$36,$S11) -> 2 | AE11: =IF($H11=1,COUNTIF($H$4:$H11,1),"") | AF11: =IF(AND($G11<>"",$G11>0,$G11<$AF$1),COUNTIFS($G$4:$G11,">0",$G$4:$G11,"<"&$AF$1),"")
A12: =REFERENTIEL!E12 -> SA-PRV-3.1 | B12: =REFERENTIEL!A12 -> Santé | C12: =REFERENTIEL!B12 -> Prévention | D12: =REFERENTIEL!C12 -> SA-PRV-3 | E12: =REFERENTIEL!H12 -> Binaire | F12: =REFERENTIEL!J12 -> 1 | G12: =IF(SAISIE!$I27="","",IF($E12="Binaire",SAISIE!$I27*100,IF($E12="Maturité",(SAISIE!$I27-1)*25,IF(OR(SAISIE!$J27="",SAISIE!$J27=0),"",MIN(100,SAISIE!$I27*$F12/SAISIE!$J27*100))))) | H12: =IF(AND($G12<>"",$G12=0),1,"") | I12: =IF(SAISIE!$K27="NA",1,"") | J12: =IF(AND(SAISIE!$K27<>"",SAISIE!$K27<>"OK",SAISIE!$K27<>"NA"),1,"") | L12: =IFERROR(INDEX($D$4:$D$134,MATCH($L11,$D$4:$D$134,0)+COUNTIF($D$4:$D$134,$L11)),"") -> SE-PRV-1 | M12: =IFERROR(INDEX($B$4:$B$134,MATCH($L12,$D$4:$D$134,0)),"") -> Sécurité | N12: =IFERROR(INDEX($C$4:$C$134,MATCH($L12,$D$4:$D$134,0)),"") -> Prévention | O12: =IF($L12="","",IFERROR(AVERAGEIF($D$4:$D$134,$L12,$G$4:$G$134),"")) | P12: =IF($L12="","",IF(COUNTIF($D$4:$D$134,$L12)=SUMIF($D$4:$D$134,$L12,$I$4:$I$134),1,"")) | R12: Environnement | S12: Conformité | T12: =IFERROR(AVERAGEIFS($O$4:$O$36,$M$4:$M$36,$R12,$N$4:$N$36,$S12),"") | U12: =COUNTIFS($M$4:$M$36,$R12,$N$4:$N$36,$S12) -> 3 | AE12: =IF($H12=1,COUNTIF($H$4:$H12,1),"") | AF12: =IF(AND($G12<>"",$G12>0,$G12<$AF$1),COUNTIFS($G$4:$G12,">0",$G$4:$G12,"<"&$AF$1),"")
A13: =REFERENTIEL!E13 -> SA-PRV-3.2 | B13: =REFERENTIEL!A13 -> Santé | C13: =REFERENTIEL!B13 -> Prévention | D13: =REFERENTIEL!C13 -> SA-PRV-3 | E13: =REFERENTIEL!H13 -> Binaire | F13: =REFERENTIEL!J13 -> 1 | G13: =IF(SAISIE!$I28="","",IF($E13="Binaire",SAISIE!$I28*100,IF($E13="Maturité",(SAISIE!$I28-1)*25,IF(OR(SAISIE!$J28="",SAISIE!$J28=0),"",MIN(100,SAISIE!$I28*$F13/SAISIE!$J28*100))))) | H13: =IF(AND($G13<>"",$G13=0),1,"") | I13: =IF(SAISIE!$K28="NA",1,"") | J13: =IF(AND(SAISIE!$K28<>"",SAISIE!$K28<>"OK",SAISIE!$K28<>"NA"),1,"") | L13: =IFERROR(INDEX($D$4:$D$134,MATCH($L12,$D$4:$D$134,0)+COUNTIF($D$4:$D$134,$L12)),"") -> SE-PRV-2 | M13: =IFERROR(INDEX($B$4:$B$134,MATCH($L13,$D$4:$D$134,0)),"") -> Sécurité | N13: =IFERROR(INDEX($C$4:$C$134,MATCH($L13,$D$4:$D$134,0)),"") -> Prévention | O13: =IF($L13="","",IFERROR(AVERAGEIF($D$4:$D$134,$L13,$G$4:$G$134),"")) | P13: =IF($L13="","",IF(COUNTIF($D$4:$D$134,$L13)=SUMIF($D$4:$D$134,$L13,$I$4:$I$134),1,"")) | R13: Social | S13: Prévention | T13: =IFERROR(AVERAGEIFS($O$4:$O$36,$M$4:$M$36,$R13,$N$4:$N$36,$S13),"") | U13: =COUNTIFS($M$4:$M$36,$R13,$N$4:$N$36,$S13) -> 2 | AE13: =IF($H13=1,COUNTIF($H$4:$H13,1),"") | AF13: =IF(AND($G13<>"",$G13>0,$G13<$AF$1),COUNTIFS($G$4:$G13,">0",$G$4:$G13,"<"&$AF$1),"")
A14: =REFERENTIEL!E14 -> SA-PRV-3.3 | B14: =REFERENTIEL!A14 -> Santé | C14: =REFERENTIEL!B14 -> Prévention | D14: =REFERENTIEL!C14 -> SA-PRV-3 | E14: =REFERENTIEL!H14 -> Taux | F14: =REFERENTIEL!J14 -> 1 | G14: =IF(SAISIE!$I29="","",IF($E14="Binaire",SAISIE!$I29*100,IF($E14="Maturité",(SAISIE!$I29-1)*25,IF(OR(SAISIE!$J29="",SAISIE!$J29=0),"",MIN(100,SAISIE!$I29*$F14/SAISIE!$J29*100))))) | H14: =IF(AND($G14<>"",$G14=0),1,"") | I14: =IF(SAISIE!$K29="NA",1,"") | J14: =IF(AND(SAISIE!$K29<>"",SAISIE!$K29<>"OK",SAISIE!$K29<>"NA"),1,"") | L14: =IFERROR(INDEX($D$4:$D$134,MATCH($L13,$D$4:$D$134,0)+COUNTIF($D$4:$D$134,$L13)),"") -> SE-PRV-3 | M14: =IFERROR(INDEX($B$4:$B$134,MATCH($L14,$D$4:$D$134,0)),"") -> Sécurité | N14: =IFERROR(INDEX($C$4:$C$134,MATCH($L14,$D$4:$D$134,0)),"") -> Prévention | O14: =IF($L14="","",IFERROR(AVERAGEIF($D$4:$D$134,$L14,$G$4:$G$134),"")) | P14: =IF($L14="","",IF(COUNTIF($D$4:$D$134,$L14)=SUMIF($D$4:$D$134,$L14,$I$4:$I$134),1,"")) | R14: Social | S14: Protection | T14: =IFERROR(AVERAGEIFS($O$4:$O$36,$M$4:$M$36,$R14,$N$4:$N$36,$S14),"") | U14: =COUNTIFS($M$4:$M$36,$R14,$N$4:$N$36,$S14) -> 3 | AE14: =IF($H14=1,COUNTIF($H$4:$H14,1),"") | AF14: =IF(AND($G14<>"",$G14>0,$G14<$AF$1),COUNTIFS($G$4:$G14,">0",$G$4:$G14,"<"&$AF$1),"")
A15: =REFERENTIEL!E15 -> SA-PRV-3.4 | B15: =REFERENTIEL!A15 -> Santé | C15: =REFERENTIEL!B15 -> Prévention | D15: =REFERENTIEL!C15 -> SA-PRV-3 | E15: =REFERENTIEL!H15 -> Binaire | F15: =REFERENTIEL!J15 -> 1 | G15: =IF(SAISIE!$I30="","",IF($E15="Binaire",SAISIE!$I30*100,IF($E15="Maturité",(SAISIE!$I30-1)*25,IF(OR(SAISIE!$J30="",SAISIE!$J30=0),"",MIN(100,SAISIE!$I30*$F15/SAISIE!$J30*100))))) | H15: =IF(AND($G15<>"",$G15=0),1,"") | I15: =IF(SAISIE!$K30="NA",1,"") | J15: =IF(AND(SAISIE!$K30<>"",SAISIE!$K30<>"OK",SAISIE!$K30<>"NA"),1,"") | L15: =IFERROR(INDEX($D$4:$D$134,MATCH($L14,$D$4:$D$134,0)+COUNTIF($D$4:$D$134,$L14)),"") -> SE-PRT-1 | M15: =IFERROR(INDEX($B$4:$B$134,MATCH($L15,$D$4:$D$134,0)),"") -> Sécurité | N15: =IFERROR(INDEX($C$4:$C$134,MATCH($L15,$D$4:$D$134,0)),"") -> Protection | O15: =IF($L15="","",IFERROR(AVERAGEIF($D$4:$D$134,$L15,$G$4:$G$134),"")) | P15: =IF($L15="","",IF(COUNTIF($D$4:$D$134,$L15)=SUMIF($D$4:$D$134,$L15,$I$4:$I$134),1,"")) | R15: Social | S15: Conformité | T15: =IFERROR(AVERAGEIFS($O$4:$O$36,$M$4:$M$36,$R15,$N$4:$N$36,$S15),"") | U15: =COUNTIFS($M$4:$M$36,$R15,$N$4:$N$36,$S15) -> 3 | AE15: =IF($H15=1,COUNTIF($H$4:$H15,1),"") | AF15: =IF(AND($G15<>"",$G15>0,$G15<$AF$1),COUNTIFS($G$4:$G15,">0",$G$4:$G15,"<"&$AF$1),"")
A16: =REFERENTIEL!E16 -> SA-PRT-1.1 | B16: =REFERENTIEL!A16 -> Santé | C16: =REFERENTIEL!B16 -> Protection | D16: =REFERENTIEL!C16 -> SA-PRT-1 | E16: =REFERENTIEL!H16 -> Maturité | F16: =REFERENTIEL!J16 -> 1 | G16: =IF(SAISIE!$I31="","",IF($E16="Binaire",SAISIE!$I31*100,IF($E16="Maturité",(SAISIE!$I31-1)*25,IF(OR(SAISIE!$J31="",SAISIE!$J31=0),"",MIN(100,SAISIE!$I31*$F16/SAISIE!$J31*100))))) | H16: =IF(AND($G16<>"",$G16=0),1,"") | I16: =IF(SAISIE!$K31="NA",1,"") | J16: =IF(AND(SAISIE!$K31<>"",SAISIE!$K31<>"OK",SAISIE!$K31<>"NA"),1,"") | L16: =IFERROR(INDEX($D$4:$D$134,MATCH($L15,$D$4:$D$134,0)+COUNTIF($D$4:$D$134,$L15)),"") -> SE-PRT-2 | M16: =IFERROR(INDEX($B$4:$B$134,MATCH($L16,$D$4:$D$134,0)),"") -> Sécurité | N16: =IFERROR(INDEX($C$4:$C$134,MATCH($L16,$D$4:$D$134,0)),"") -> Protection | O16: =IF($L16="","",IFERROR(AVERAGEIF($D$4:$D$134,$L16,$G$4:$G$134),"")) | P16: =IF($L16="","",IF(COUNTIF($D$4:$D$134,$L16)=SUMIF($D$4:$D$134,$L16,$I$4:$I$134),1,"")) | AE16: =IF($H16=1,COUNTIF($H$4:$H16,1),"") | AF16: =IF(AND($G16<>"",$G16>0,$G16<$AF$1),COUNTIFS($G$4:$G16,">0",$G$4:$G16,"<"&$AF$1),"")
A17: =REFERENTIEL!E17 -> SA-PRT-1.2 | B17: =REFERENTIEL!A17 -> Santé | C17: =REFERENTIEL!B17 -> Protection | D17: =REFERENTIEL!C17 -> SA-PRT-1 | E17: =REFERENTIEL!H17 -> Maturité | F17: =REFERENTIEL!J17 -> 1 | G17: =IF(SAISIE!$I32="","",IF($E17="Binaire",SAISIE!$I32*100,IF($E17="Maturité",(SAISIE!$I32-1)*25,IF(OR(SAISIE!$J32="",SAISIE!$J32=0),"",MIN(100,SAISIE!$I32*$F17/SAISIE!$J32*100))))) | H17: =IF(AND($G17<>"",$G17=0),1,"") | I17: =IF(SAISIE!$K32="NA",1,"") | J17: =IF(AND(SAISIE!$K32<>"",SAISIE!$K32<>"OK",SAISIE!$K32<>"NA"),1,"") | L17: =IFERROR(INDEX($D$4:$D$134,MATCH($L16,$D$4:$D$134,0)+COUNTIF($D$4:$D$134,$L16)),"") -> SE-PRT-3 | M17: =IFERROR(INDEX($B$4:$B$134,MATCH($L17,$D$4:$D$134,0)),"") -> Sécurité | N17: =IFERROR(INDEX($C$4:$C$134,MATCH($L17,$D$4:$D$134,0)),"") -> Protection | O17: =IF($L17="","",IFERROR(AVERAGEIF($D$4:$D$134,$L17,$G$4:$G$134),"")) | P17: =IF($L17="","",IF(COUNTIF($D$4:$D$134,$L17)=SUMIF($D$4:$D$134,$L17,$I$4:$I$134),1,"")) | AE17: =IF($H17=1,COUNTIF($H$4:$H17,1),"") | AF17: =IF(AND($G17<>"",$G17>0,$G17<$AF$1),COUNTIFS($G$4:$G17,">0",$G$4:$G17,"<"&$AF$1),"")
A18: =REFERENTIEL!E18 -> SA-PRT-1.3 | B18: =REFERENTIEL!A18 -> Santé | C18: =REFERENTIEL!B18 -> Protection | D18: =REFERENTIEL!C18 -> SA-PRT-1 | E18: =REFERENTIEL!H18 -> Maturité | F18: =REFERENTIEL!J18 -> 1 | G18: =IF(SAISIE!$I33="","",IF($E18="Binaire",SAISIE!$I33*100,IF($E18="Maturité",(SAISIE!$I33-1)*25,IF(OR(SAISIE!$J33="",SAISIE!$J33=0),"",MIN(100,SAISIE!$I33*$F18/SAISIE!$J33*100))))) | H18: =IF(AND($G18<>"",$G18=0),1,"") | I18: =IF(SAISIE!$K33="NA",1,"") | J18: =IF(AND(SAISIE!$K33<>"",SAISIE!$K33<>"OK",SAISIE!$K33<>"NA"),1,"") | L18: =IFERROR(INDEX($D$4:$D$134,MATCH($L17,$D$4:$D$134,0)+COUNTIF($D$4:$D$134,$L17)),"") -> SE-CNF-1 | M18: =IFERROR(INDEX($B$4:$B$134,MATCH($L18,$D$4:$D$134,0)),"") -> Sécurité | N18: =IFERROR(INDEX($C$4:$C$134,MATCH($L18,$D$4:$D$134,0)),"") -> Conformité | O18: =IF($L18="","",IFERROR(AVERAGEIF($D$4:$D$134,$L18,$G$4:$G$134),"")) | P18: =IF($L18="","",IF(COUNTIF($D$4:$D$134,$L18)=SUMIF($D$4:$D$134,$L18,$I$4:$I$134),1,"")) | AE18: =IF($H18=1,COUNTIF($H$4:$H18,1),"") | AF18: =IF(AND($G18<>"",$G18>0,$G18<$AF$1),COUNTIFS($G$4:$G18,">0",$G$4:$G18,"<"&$AF$1),"")
A19: =REFERENTIEL!E19 -> SA-PRT-1.4 | B19: =REFERENTIEL!A19 -> Santé | C19: =REFERENTIEL!B19 -> Protection | D19: =REFERENTIEL!C19 -> SA-PRT-1 | E19: =REFERENTIEL!H19 -> Binaire | F19: =REFERENTIEL!J19 -> 1 | G19: =IF(SAISIE!$I34="","",IF($E19="Binaire",SAISIE!$I34*100,IF($E19="Maturité",(SAISIE!$I34-1)*25,IF(OR(SAISIE!$J34="",SAISIE!$J34=0),"",MIN(100,SAISIE!$I34*$F19/SAISIE!$J34*100))))) | H19: =IF(AND($G19<>"",$G19=0),1,"") | I19: =IF(SAISIE!$K34="NA",1,"") | J19: =IF(AND(SAISIE!$K34<>"",SAISIE!$K34<>"OK",SAISIE!$K34<>"NA"),1,"") | L19: =IFERROR(INDEX($D$4:$D$134,MATCH($L18,$D$4:$D$134,0)+COUNTIF($D$4:$D$134,$L18)),"") -> SE-CNF-2 | M19: =IFERROR(INDEX($B$4:$B$134,MATCH($L19,$D$4:$D$134,0)),"") -> Sécurité | N19: =IFERROR(INDEX($C$4:$C$134,MATCH($L19,$D$4:$D$134,0)),"") -> Conformité | O19: =IF($L19="","",IFERROR(AVERAGEIF($D$4:$D$134,$L19,$G$4:$G$134),"")) | P19: =IF($L19="","",IF(COUNTIF($D$4:$D$134,$L19)=SUMIF($D$4:$D$134,$L19,$I$4:$I$134),1,"")) | AE19: =IF($H19=1,COUNTIF($H$4:$H19,1),"") | AF19: =IF(AND($G19<>"",$G19>0,$G19<$AF$1),COUNTIFS($G$4:$G19,">0",$G$4:$G19,"<"&$AF$1),"")
A20: =REFERENTIEL!E20 -> SA-PRT-2.1 | B20: =REFERENTIEL!A20 -> Santé | C20: =REFERENTIEL!B20 -> Protection | D20: =REFERENTIEL!C20 -> SA-PRT-2 | E20: =REFERENTIEL!H20 -> Binaire | F20: =REFERENTIEL!J20 -> 1 | G20: =IF(SAISIE!$I35="","",IF($E20="Binaire",SAISIE!$I35*100,IF($E20="Maturité",(SAISIE!$I35-1)*25,IF(OR(SAISIE!$J35="",SAISIE!$J35=0),"",MIN(100,SAISIE!$I35*$F20/SAISIE!$J35*100))))) | H20: =IF(AND($G20<>"",$G20=0),1,"") | I20: =IF(SAISIE!$K35="NA",1,"") | J20: =IF(AND(SAISIE!$K35<>"",SAISIE!$K35<>"OK",SAISIE!$K35<>"NA"),1,"") | L20: =IFERROR(INDEX($D$4:$D$134,MATCH($L19,$D$4:$D$134,0)+COUNTIF($D$4:$D$134,$L19)),"") -> SE-CNF-3 | M20: =IFERROR(INDEX($B$4:$B$134,MATCH($L20,$D$4:$D$134,0)),"") -> Sécurité | N20: =IFERROR(INDEX($C$4:$C$134,MATCH($L20,$D$4:$D$134,0)),"") -> Conformité | O20: =IF($L20="","",IFERROR(AVERAGEIF($D$4:$D$134,$L20,$G$4:$G$134),"")) | P20: =IF($L20="","",IF(COUNTIF($D$4:$D$134,$L20)=SUMIF($D$4:$D$134,$L20,$I$4:$I$134),1,"")) | AE20: =IF($H20=1,COUNTIF($H$4:$H20,1),"") | AF20: =IF(AND($G20<>"",$G20>0,$G20<$AF$1),COUNTIFS($G$4:$G20,">0",$G$4:$G20,"<"&$AF$1),"")
A21: =REFERENTIEL!E21 -> SA-PRT-2.2 | B21: =REFERENTIEL!A21 -> Santé | C21: =REFERENTIEL!B21 -> Protection | D21: =REFERENTIEL!C21 -> SA-PRT-2 | E21: =REFERENTIEL!H21 -> Binaire | F21: =REFERENTIEL!J21 -> 1 | G21: =IF(SAISIE!$I36="","",IF($E21="Binaire",SAISIE!$I36*100,IF($E21="Maturité",(SAISIE!$I36-1)*25,IF(OR(SAISIE!$J36="",SAISIE!$J36=0),"",MIN(100,SAISIE!$I36*$F21/SAISIE!$J36*100))))) | H21: =IF(AND($G21<>"",$G21=0),1,"") | I21: =IF(SAISIE!$K36="NA",1,"") | J21: =IF(AND(SAISIE!$K36<>"",SAISIE!$K36<>"OK",SAISIE!$K36<>"NA"),1,"") | L21: =IFERROR(INDEX($D$4:$D$134,MATCH($L20,$D$4:$D$134,0)+COUNTIF($D$4:$D$134,$L20)),"") -> EN-PRV-1 | M21: =IFERROR(INDEX($B$4:$B$134,MATCH($L21,$D$4:$D$134,0)),"") -> Environnement | N21: =IFERROR(INDEX($C$4:$C$134,MATCH($L21,$D$4:$D$134,0)),"") -> Prévention | O21: =IF($L21="","",IFERROR(AVERAGEIF($D$4:$D$134,$L21,$G$4:$G$134),"")) | P21: =IF($L21="","",IF(COUNTIF($D$4:$D$134,$L21)=SUMIF($D$4:$D$134,$L21,$I$4:$I$134),1,"")) | AE21: =IF($H21=1,COUNTIF($H$4:$H21,1),"") | AF21: =IF(AND($G21<>"",$G21>0,$G21<$AF$1),COUNTIFS($G$4:$G21,">0",$G$4:$G21,"<"&$AF$1),"")
